Traceback (most recent call last):
  File "/opt/homebrew/anaconda3/lib/python3.11/site-packages/jupyter_cache/executors/utils.py", line 58, in single_nb_execution
    executenb(
  File "/opt/homebrew/anaconda3/lib/python3.11/site-packages/nbclient/client.py", line 1204, in execute
    return NotebookClient(nb=nb, resources=resources, km=km, **kwargs).execute()
           ^^^^^^^^^^^^^^^^^^^^^^^^^^^^^^^^^^^^^^^^^^^^^^^^^^^^^^^^^^^^^^^^^^^^^
  File "/opt/homebrew/anaconda3/lib/python3.11/site-packages/nbclient/util.py", line 84, in wrapped
    return just_run(coro(*args, **kwargs))
           ^^^^^^^^^^^^^^^^^^^^^^^^^^^^^^^
  File "/opt/homebrew/anaconda3/lib/python3.11/site-packages/nbclient/util.py", line 62, in just_run
    return loop.run_until_complete(coro)
           ^^^^^^^^^^^^^^^^^^^^^^^^^^^^^
  File "/opt/homebrew/anaconda3/lib/python3.11/asyncio/base_events.py", line 650, in run_until_complete
    return future.result()
           ^^^^^^^^^^^^^^^
  File "/opt/homebrew/anaconda3/lib/python3.11/contextlib.py", line 222, in __aexit__
    await self.gen.athrow(typ, value, traceback)
  File "/opt/homebrew/anaconda3/lib/python3.11/site-packages/nbclient/client.py", line 608, in async_setup_kernel
    yield
  File "/opt/homebrew/anaconda3/lib/python3.11/site-packages/nbclient/client.py", line 663, in async_execute
    await self.async_execute_cell(
  File "/opt/homebrew/anaconda3/lib/python3.11/site-packages/nbclient/client.py", line 965, in async_execute_cell
    await self._check_raise_for_error(cell, cell_index, exec_reply)
  File "/opt/homebrew/anaconda3/lib/python3.11/site-packages/nbclient/client.py", line 862, in _check_raise_for_error
    raise CellExecutionError.from_cell_and_msg(cell, exec_reply_content)
nbclient.exceptions.CellExecutionError: An error occurred while executing the following cell:
------------------
mod = inventory_model(label='production',max_inventory=25)
mod.dp=.25
mod.demand = int((1-mod.dp)/mod.dp)
mod.c = .25
mod.p = 3.5
mod.r = 0.4
mod.Î² = 0.9
mod.demand_pr(plot=True)
mod = solver_backwards_induction(mod,T=15)
plot_solution(mod)

ev,q = solve_vfi(mod)
solve_show(mod)
print('Optimal orders of new inventory for d,x:\n(d in rows, x in columns)')
print(q)

------------------

[0;31m---------------------------------------------------------------------------[0m
[0;31mAttributeError[0m                            Traceback (most recent call last)
Cell [0;32mIn[10], line 8[0m
[1;32m      6[0m mod[38;5;241m.[39mr [38;5;241m=[39m [38;5;241m0.4[39m
[1;32m      7[0m mod[38;5;241m.[39mÎ² [38;5;241m=[39m [38;5;241m0.9[39m
[0;32m----> 8[0m mod[38;5;241m.[39mdemand_pr(plot[38;5;241m=[39m[38;5;28;01mTrue[39;00m)
[1;32m      9[0m mod [38;5;241m=[39m solver_backwards_induction(mod,T[38;5;241m=[39m[38;5;241m15[39m)
[1;32m     10[0m plot_solution(mod)

[0;31mAttributeError[0m: 'inventory_model' object has no attribute 'demand_pr'
AttributeError: 'inventory_model' object has no attribute 'demand_pr'

